Workbook
Name ASIENTO_FAC_COMPRA_1: 'LIBRO DIARIO'!$A$9
Name ASIENTO_FAC_COMPRA_10: 'LIBRO DIARIO'!$A$64
Name ASIENTO_FAC_COMPRA_11: 'LIBRO DIARIO'!$A$69
Name ASIENTO_FAC_COMPRA_12: 'LIBRO DIARIO'!$A$76
Name ASIENTO_FAC_COMPRA_13: 'LIBRO DIARIO'!$A$81
Name ASIENTO_FAC_COMPRA_14: 'LIBRO DIARIO'!$A$86
Name ASIENTO_FAC_COMPRA_15: 'LIBRO DIARIO'!$A$93
Name ASIENTO_FAC_COMPRA_16: 'LIBRO DIARIO'!$A$100
Name ASIENTO_FAC_COMPRA_17: 'LIBRO DIARIO'!$A$107
Name ASIENTO_FAC_COMPRA_18: 'LIBRO DIARIO'!$A$116
Name ASIENTO_FAC_COMPRA_19: 'LIBRO DIARIO'!$A$123
Name ASIENTO_FAC_COMPRA_2: 'LIBRO DIARIO'!$A$14
Name ASIENTO_FAC_COMPRA_20: 'LIBRO DIARIO'!$A$126
Name ASIENTO_FAC_COMPRA_21: 'LIBRO DIARIO'!$A$131
Name ASIENTO_FAC_COMPRA_22: 'LIBRO DIARIO'!$A$136
Name ASIENTO_FAC_COMPRA_23: 'LIBRO DIARIO'!$A$141
Name ASIENTO_FAC_COMPRA_24: 'LIBRO DIARIO'!$A$148
Name ASIENTO_FAC_COMPRA_25: 'LIBRO DIARIO'!$A$153
Name ASIENTO_FAC_COMPRA_26: 'LIBRO DIARIO'!$A$159
Name ASIENTO_FAC_COMPRA_27: 'LIBRO DIARIO'!$A$167
Name ASIENTO_FAC_COMPRA_28: 'LIBRO DIARIO'!$A$175
Name ASIENTO_FAC_COMPRA_29: 'LIBRO DIARIO'!$A$183
Name ASIENTO_FAC_COMPRA_3: 'LIBRO DIARIO'!$A$21
Name ASIENTO_FAC_COMPRA_30: 'LIBRO DIARIO'!$A$193
Name ASIENTO_FAC_COMPRA_31: 'LIBRO DIARIO'!$A$201
Name ASIENTO_FAC_COMPRA_32: 'LIBRO DIARIO'!$A$205
Name ASIENTO_FAC_COMPRA_33: 'LIBRO DIARIO'!$A$211
Name ASIENTO_FAC_COMPRA_34: 'LIBRO DIARIO'!$A$217
Name ASIENTO_FAC_COMPRA_35: 'LIBRO DIARIO'!$A$223
Name ASIENTO_FAC_COMPRA_36: 'LIBRO DIARIO'!$A$231
Name ASIENTO_FAC_COMPRA_37: 'LIBRO DIARIO'!$A$237
Name ASIENTO_FAC_COMPRA_38: 'LIBRO DIARIO'!$A$243
Name ASIENTO_FAC_COMPRA_39: 'LIBRO DIARIO'!$A$251
Name ASIENTO_FAC_COMPRA_4: 'LIBRO DIARIO'!$A$28
Name ASIENTO_FAC_COMPRA_40: 'LIBRO DIARIO'!$A$259
Name ASIENTO_FAC_COMPRA_41: 'LIBRO DIARIO'!$A$267
Name ASIENTO_FAC_COMPRA_42: 'LIBRO DIARIO'!$A$277
Name ASIENTO_FAC_COMPRA_5: 'LIBRO DIARIO'!$A$35
Name ASIENTO_FAC_COMPRA_6: 'LIBRO DIARIO'!$A$44
Name ASIENTO_FAC_COMPRA_7: 'LIBRO DIARIO'!$A$51
Name ASIENTO_FAC_COMPRA_8: 'LIBRO DIARIO'!$A$54
Name ASIENTO_FAC_COMPRA_9: 'LIBRO DIARIO'!$A$59
Name FACTURA_COMPRA___1: COMPRAS!$C$6
Name FACTURA_COMPRA___10: COMPRAS!$C$251
Name FACTURA_COMPRA___11: COMPRAS!$C$274
Name FACTURA_COMPRA___12: COMPRAS!$C$303
Name FACTURA_COMPRA___13: COMPRAS!$C$329
Name FACTURA_COMPRA___14: COMPRAS!$C$357
Name FACTURA_COMPRA___15: COMPRAS!$C$385
Name FACTURA_COMPRA___16: COMPRAS!$C$413
Name FACTURA_COMPRA___17: COMPRAS!$C$441
Name FACTURA_COMPRA___18: COMPRAS!$C$474
Name FACTURA_COMPRA___19: COMPRAS!$C$505
Name FACTURA_COMPRA___2: COMPRAS!$C$34
Name FACTURA_COMPRA___20: COMPRAS!$C$528
Name FACTURA_COMPRA___21: COMPRAS!$C$551
Name FACTURA_COMPRA___22: COMPRAS!$C$574
Name FACTURA_COMPRA___23: COMPRAS!$C$597
Name FACTURA_COMPRA___24: COMPRAS!$C$626
Name FACTURA_COMPRA___25: COMPRAS!$C$652

Sheet PRODUCTOS
A1: PRODUCTO INVENTARIO | C1: IVA
A2: I001 | B2: ACEITE DE VASELINA GL.QF | C2: SI
A3: I002 | B3: Bastidor | C3: SI
A4: I003 | B4: Tira Color Dorado Con Filos Negros De 7.5 Ancho | C4: SI
A5: I004 | B5: Blanca Estucada Semimate | C5: SI
A6: I005 | B6: Chocolate Estucada Semimate | C6: SI
A7: I006 | B7: Azúl Con Dorado | C7: SI
A8: I007 | B8: pino natural procesado con ceja izq | C8: SI
A9: I008 | B9: pino natural peq. Procesado ceja | C9: SI
A10: I009 | B10: pino natural procesado con ceja der | C10: SI
A11: I0010 | B11: Labrada/Verde Con Beige | C11: NO
A12: I0011 | B12: Verde Con Dorado | C12: NO
A13: I0012 | B13: Dorado Con Trenza | C13: NO
... A15: I0014 | B15: Plateada Llana | C15: NO
A18: GASTOS O SERVICIOS
A19: CT-COMPRAS49127 | B19: Arriendo de Local | C19: SI
A20: CT-COMPRAS57289 | B20: ANUNCIO PUBLICITARIO | C20: SI
A21: CT-COMPRAS52464 | B21: RESMAS DE PAPEL BOND | C21: SI | D21: UTILES Y PAPELERIA
A22: CT-COMPRAS4105 | B22: CAJAS DE ESFEROS | C22: SI | D22: UTILES Y PAPELERIA
A23: CT-COMPRAS49110 | B23: AGENDAS | C23: SI | D23: UTILES Y PAPELERIA
A24: CT-COMPRAS13417 | B24: ALMUERZOS | C24: SI
A25: CT-COMPRAS45097 | B25: PORTATIL HP | C25: SI
A26: CT-COMPRAS8826 | B26: PAGO ENERGIA | C26: SI
A27: CT-COMPRAS45439 | B27: MANTENIMIENTO EDIFICIO | C27: SI
B28: PEGANOL | C28: NO | D28: UTILES Y PAPELERIA
B29: ESCARCHA | C29: NO | D29: UTILES Y PAPELERIA
B30: CARTULINA | C30: NO | D30: UTILES Y PAPELERIA
A33: VENTA SERVICIO
A34: SP300 | B34: SERVICIOS PRESTADOS 300 | C34: SI
A35: SP1000 | B35: SERVICIOS PRESTADOS 1000 | C35: SI
A36: SP200 | B36: SERVICIOS PRESTADOS 200 | C36: SI
A37: SP2500 | B37: SERVICIOS PRESTADOS 2500 | C37: SI

Sheet FACTURA COMPRA
A3: DESCRIPCION | C3: DOCUMENTO # | D3: PROVEEDOR | E3: FECHA EMISIÓN | F3: SUBTOTAL | G3: RETENCION | H3: TOTAL
A4: ESTADO | B4: =+COMPRAS!C32 -> Pendiente | C4: =+CONCATENATE(COMPRAS!C6," ",COMPRAS!C26) -> FACTURA COMPRA # 1 001-001-100 | D4: =CONCATENATE(COMPRAS!C8," / ",COMPRAS!C9) -> VICTOR LOPEZ SANDOVAL / 1712458544001 | E4: =+COMPRAS!C27 -> 43497 | F4: =+COMPRAS!E15+COMPRAS!E16-COMPRAS!E17 -> 424.4316 | G4: =+COMPRAS!M24 -> 55.176108 | H4: =+COMPRAS!N24 -> 420.18728
A5: TIPO | B5: =+COMPRAS!C13 -> FACTURA
A6: CREDITO | B6: =+COMPRAS!C31 -> 420.18728
A7: ESTADO | B7: =+COMPRAS!C60 -> Emitido | C7: =+CONCATENATE(COMPRAS!C34," ",COMPRAS!C54) -> FACTURA COMPRA # 2 001-001-101 | D7: =CONCATENATE(COMPRAS!C36," / ",COMPRAS!C37) -> VICTOR LOPEZ SANDOVAL / 1712458544001 | E7: =+COMPRAS!C44 -> 43497 | F7: =+COMPRAS!E43+COMPRAS!E44-COMPRAS!E45 -> 424.4316 | G7: =+COMPRAS!M52 -> 49.234066 | H7: =+COMPRAS!N52 -> 426.12933
A8: TIPO | B8: =+COMPRAS!C41 -> FACTURA
A9: CREDITO | B9: =+IF(COMPRAS!C60="Emitido","No",0) -> No
A10: ESTADO | B10: =+COMPRAS!C88 -> Emitido | C10: =+CONCATENATE(COMPRAS!C62," ",COMPRAS!C82) -> FACTURA COMPRA # 3 001-001-102 | D10: =CONCATENATE(COMPRAS!C64," / ",COMPRAS!C65) -> VICTOR LOPEZ SANDOVAL / 1712458544001 | E10: =+COMPRAS!C72 -> 43497 | F10: =+COMPRAS!E71+COMPRAS!E72-COMPRAS!E73 -> 424.4316 | G10: =+COMPRAS!M80 -> 33.954528 | H10: =+COMPRAS!N80 -> 441.40886
A11: TIPO | B11: =+COMPRAS!C69 -> FACTURA
A12: CREDITO | B12: =+IF(COMPRAS!C88="Emitido","No",0) -> No
A13: ESTADO | B13: =+COMPRAS!C116 -> Emitido | C13: =+CONCATENATE(COMPRAS!C90," ",COMPRAS!C110) -> FACTURA COMPRA # 4 001-001-103 | D13: =CONCATENATE(COMPRAS!C92," / ",COMPRAS!C93) -> ILUMAX / 1708492408001 | E13: =+COMPRAS!C100 -> 43498 | F13: =+COMPRAS!E99+COMPRAS!E100-COMPRAS!E101 -> 1180.8087 | G13: =+COMPRAS!M108 -> 110.99602 | H13: =+COMPRAS!N108 -> 1211.5097
A14: TIPO | B14: =+COMPRAS!C97 -> FACTURA
A15: CREDITO | B15: =+IF(COMPRAS!C116="Emitido","No",0) -> No
A16: ESTADO | B16: =+COMPRAS!C149 -> Emitido | C16: =+CONCATENATE(COMPRAS!C118," ",COMPRAS!C138) -> FACTURA COMPRA # 5 001-001-104 | D16: =CONCATENATE(COMPRAS!C120," / ",COMPRAS!C121) -> ILUMAX / 1708492408001 | E16: =+COMPRAS!C128 -> 43498 | F16: =+COMPRAS!E127+COMPRAS!E128-COMPRAS!E129 -> 1180.8087 | G16: =+COMPRAS!M136 -> 108.6344 | H16: =+COMPRAS!N136 -> 1213.8713
A17: TIPO | B17: =+COMPRAS!C125 -> FACTURA
A18: CREDITO | B18: =+IF(COMPRAS!C149="Emitido","No",0) -> No
A19: ESTADO | B19: =+COMPRAS!C180 -> Pendiente | C19: =+CONCATENATE(COMPRAS!C151," ",COMPRAS!C171) -> FACTURA COMPRA # 6 001-001-105 | D19: =CONCATENATE(COMPRAS!C153," / ",COMPRAS!C154) -> ILUMAX / 1708492408001 | E19: =+COMPRAS!C161 -> 43498 | F19: =+COMPRAS!E160+COMPRAS!E161-COMPRAS!E162 -> 1180.8087 | G19: =+COMPRAS!M169 -> 51.955583 | H19: =+COMPRAS!N169 -> 1270.5502
A20: TIPO | B20: =+COMPRAS!C158 -> FACTURA
A21: CREDITO | B21: =+COMPRAS!C179 -> 508.22006
A22: ESTADO | B22: =+COMPRAS!C203 -> Pendiente | C22: =+CONCATENATE(COMPRAS!C182," ",COMPRAS!C193,"-",COMPRAS!C194,"-",COMPRAS!C195) -> FACTURA COMPRA # 7 001-001-106 | D22: =CONCATENATE(COMPRAS!C184," / ",COMPRAS!C185) -> VICTOR LOPEZ SANDOVAL / 1712458544001 | E22: =+COMPRAS!C192 -> 43497 | F22: =+COMPRAS!E191+COMPRAS!E192-COMPRAS!E193 -> 424.4316 | G22: =+COMPRAS!M142 -> 0 | H22: =+COMPRAS!E195 -> 475.36339
A23: TIPO | B23: =+COMPRAS!C189 -> FACTURA
A24: CREDITO | B24: =+COMPRAS!C202 -> 475.36339
A25: ESTADO | B25: =+COMPRAS!C226 -> Emitido | C25: =+CONCATENATE(COMPRAS!C205," ",COMPRAS!C216,"-",COMPRAS!C217,"-",COMPRAS!C218) -> FACTURA COMPRA # 8 001-001-107 | D25: =CONCATENATE(COMPRAS!C207," / ",COMPRAS!C208) -> VICTOR LOPEZ SANDOVAL / 1712458544001 | E25: =+COMPRAS!C215 -> 43497 | F25: =+COMPRAS!E214+COMPRAS!E215-COMPRAS!E216 -> 501.8516 | G25: =+COMPRAS!M175 -> 0 | H25: =+COMPRAS!E218 -> 562.07379
A26: TIPO | B26: =+COMPRAS!C212 -> FACTURA
A27: CREDITO | B27: =+IF(COMPRAS!C226="Emitido","No",0) -> No
A28: ESTADO | B28: =+COMPRAS!C249 -> Emitido | C28: =+CONCATENATE(COMPRAS!C228," ",COMPRAS!C239,"-",COMPRAS!C240,"-",COMPRAS!C241) -> FACTURA COMPRA # 9 001-001-108 | D28: =CONCATENATE(COMPRAS!C230," / ",COMPRAS!C231) -> VICTOR LOPEZ SANDOVAL / 1712458544001 | E28: =+COMPRAS!C238 -> 43497 | F28: =+COMPRAS!E237+COMPRAS!E238-COMPRAS!E239 -> 405.8116 | G28: =+COMPRAS!M148 -> 0 | H28: =+COMPRAS!E241 -> 454.50899
A29: TIPO | B29: =+COMPRAS!C235 -> FACTURA
A30: CREDITO | B30: =+IF(COMPRAS!C249="Emitido","No",0) -> No
A31: ESTADO | B31: =+COMPRAS!C272 -> Emitido | C31: =+CONCATENATE(COMPRAS!C251," ",COMPRAS!C262,"-",COMPRAS!C263,"-",COMPRAS!C264) -> FACTURA COMPRA # 10 001-001-109 | D31: =CONCATENATE(COMPRAS!C253," / ",COMPRAS!C254) -> ILUMAX / 1708492408001 | E31: =+COMPRAS!C261 -> 43498 | F31: =+COMPRAS!E260+COMPRAS!E261-COMPRAS!E262 -> 1180.8087 | G31: =+COMPRAS!M181 -> 0 | H31: =+COMPRAS!E264 -> 1322.5057
A32: TIPO | B32: =+COMPRAS!C258 -> FACTURA
A33: CREDITO | B33: =+IF(COMPRAS!C272="Emitido","No",0) -> No
A34: ESTADO | B34: =+COMPRAS!C301 -> Emitido | C34: =+CONCATENATE(COMPRAS!C274," ",COMPRAS!C285,"-",COMPRAS!C286,"-",COMPRAS!C287) -> FACTURA COMPRA # 11 001-001-110 | D34: =CONCATENATE(COMPRAS!C276," / ",COMPRAS!C277) -> ILUMAX / 1708492408001 | E34: =+COMPRAS!C284 -> 43498 | F34: =+COMPRAS!E283+COMPRAS!E284-COMPRAS!E285 -> 1180.8087 | G34: =+COMPRAS!M154 -> 0 | H34: =+COMPRAS!E287 -> 1322.5057
A35: TIPO | B35: =+COMPRAS!C281 -> FACTURA
A36: CREDITO | B36: =+IF(COMPRAS!C301="Emitido","No",0) -> No
A37: ESTADO | B37: =+COMPRAS!C317 -> Pendiente | C37: =+CONCATENATE(COMPRAS!C303," ",COMPRAS!C314,"-",COMPRAS!C315,"-",COMPRAS!C316) -> FACTURA COMPRA # 12 001-001-111 | D37: =CONCATENATE(COMPRAS!C305," / ",COMPRAS!C306) -> ILUMAX / 1708492408001 | E37: =+COMPRAS!C313 -> 43498 | F37: =+COMPRAS!E312+COMPRAS!E313-COMPRAS!E314 -> 1180.8087 | G37: =+COMPRAS!M187 -> 0 | H37: =+COMPRAS!E316 -> 1322.5057
A38: TIPO | B38: =+COMPRAS!C310 -> FACTURA
A39: CREDITO | B39: =+COMPRAS!C326 -> 529.0023

Sheet COMPRAS
A1: Nro Comprobante de autorizacion de retenciones
A2: G-EMPRESA-DOCUMENTOS AUTORIZADOS SRI
A3: COMPROBANTE DE RENTECION | D3: 999999999
A6: I-SD-R | B6: Deuda | C6: FACTURA COMPRA # 1
B7: FACTURA COMPRA
B8: Proveedor | C8: VICTOR LOPEZ SANDOVAL | D8: CANT | E8: CODIGO | F8: IVA | G8: PRODUCTO/DESCRIP | H8: P. UNI | I8: SUBT 0% | J8: SUBT 12% | K8: DESC % | L8: DESC $ | M8: DESC TOTAL | N8: IVA | O8: TOTAL | P8: CONTABILIDAD | Q8: NRO CUENTA | R8: TIPO
B9: idProv | C9: 1712458544001 | D9: 61 | E9: 396-12 | F9: 0.12 | G9: ACEITE DE VASELINA GL.QF | H9: 1.45 | I9: =+IF(F9=0%,D9*H9,0) -> 0 | J9: =+IF(F9=12%,D9*H9,0) -> 88.45 | K9: 0 | L9: 0 | M9: =+J9*K9 -> 0 | N9: =+(J9-M9)*F9 -> 10.614 | O9: =+J9-M9+N9 -> 99.064 | P9: INVENTARIO | Q9: 1.1.02.04.001 | R9: INVENTARIO
B10: tpIdProv | C10: 01 | D10: 56.21 | E10: 396-2507 | F10: 0.12 | G10: Bastidor | H10: 2.96 | I10: =+IF(F10=0%,D10*H10,0) -> 0 | J10: =+IF(F10=12%,D10*H10,0) -> 166.3816 | K10: 0 | L10: 0 | M10: =+J10*K10 -> 0 | N10: =+(J10-M10)*F10 -> 19.965792 | O10: =+J10-M10+N10 -> 186.34739 | P10: INVENTARIO | Q10: 1.1.02.04.001 | R10: INVENTARIO
B11: Sustento T | C11: INVENTARIO CREDITO TRIBUTARIO PARA DECLARACION DE IVA | D11: 49 | E11: 396-306 | F11: 0.12 | G11: Tira Color Dorado Con Filos Negros De 7.5 Ancho | H11: 3.15 | I11: =+IF(F11=0%,D11*H11,0) -> 0 | J11: =+IF(F11=12%,D11*H11,0) -> 154.35 | K11: 0 | L11: 0 | M11: =+J11*K11 -> 0 | N11: =+(J11-M11)*F11 -> 18.522 | O11: =+J11-M11+N11 -> 172.872 | P11: INVENTARIO | Q11: 1.1.02.04.001 | R11: INVENTARIO
B12: codSustento | C12: 06 | D12: 12.2 | E12: 362-2889 | F12: 0.12 | G12: Blanca Estucada Semimate | H12: 1.25 | I12: =+IF(F12=0%,D12*H12,0) -> 0 | J12: =+IF(F12=12%,D12*H12,0) -> 15.25 | K12: 0 | L12: 0 | M12: =+J12*K12 -> 0 | N12: =+(J12-M12)*F12 -> 1.83 | O12: =+J12-M12+N12 -> 17.08 | P12: INVENTARIO | Q12: 1.1.02.04.001 | R12: INVENTARIO
B13: Tipo Comp Aut | C13: FACTURA
B14: tipoComprobante | C14: 1
B15: autorizacion | C15: 1120335551 | D15: SUBT 0% | E15: =+SUM(I9:I12) -> 0
B16: Fecha Emi | C16: 43497 | D16: SUBTOTAL 12% | E16: =+SUM(J9:J14) -> 424.4316
B17: Establecimiento | C17: 001 | D17: DESCUENTO | E17: =SUM(M9:M14) -> 0 | G17: INGRESE MAL EL SUSTENTO
B18: Punto Emision | C18: 001 | D18: IVA | E18: =SUM(N9:N14) -> 50.931792
B19: Secuencial | C19: 100 | D19: TOTAL | E19: =SUM(O9:O14) -> 475.36339
B22: RETENCION FACTURA COMPRA
B23: Establecimiento Ret1 | C23: 001 | D23: CONTABILIDAD | E23: CUENTA CONT. | G23: BASE IMPONIBLE | H23: IMPUESTO | J23: PORCENTAJE RETENCION | L23: VALOR RET. | M23: TOTAL RET | N23: TOTAL FACT - RET
B24: Pto Emision Ret1 | C24: 001 | D24: 2.1.01.07.006 | E24: Retencion IVA por pagar 100% | G24: 731 | H24: IVA | J24: 1 | L24: =+E18*J24 -> 50.931792 | M24: =+L24+L25 -> 55.176108 | N24: =+E19-M24 -> 420.18728
B25: Secuencial Ret 1 | C25: 501 | D25: 2.1.01.06.001 | E25: Impuesto a la renta por pagar 1% | G25: 309 | H25: RENTA | J25: 0.01 | L25: =(E16+E15-E17)*J25 -> 4.244316
B26: Nro Factura | C26: =+CONCATENATE(C17,"-",C18,"-",C19) -> 001-001-100
B27: Fecha | C27: =+C16 -> 43497
B28: Tipo de Desgloce | C28: Normal | E28: ASIENTO DIARIO
B29: Boton | C29: Pendiente | E29: KARDEX
B30: Cuenta Contable | C30: Proveedores
B31: Valor a pagar | C31: =+E19-M24 -> 420.18728
B32: Estado | C32: Pendiente
A34: I-SD-R | B34: Efectivo | C34: FACTURA COMPRA # 2
B35: FACTURA COMPRA
B36: Proveedor | C36: VICTOR LOPEZ SANDOVAL | D36: CANT | E36: CODIGO | F36: IVA | G36: PRODUCTO/DESCRIP | H36: P. UNI | I36: SUBT 0% | J36: SUBT 12% | K36: DESC % | L36: DESC $ | M36: DESC TOTAL | N36: IVA | O36: TOTAL | P36: CONTABILIDAD | Q36: NRO CUENTA | R36: TIPO
B37: idProv | C37: 1712458544001 | D37: 61 | E37: 396-12 | F37: 0.12 | G37: ACEITE DE VASELINA GL.QF | H37: 1.45 | I37: =+IF(F37=0%,D37*H37,0) -> 0 | J37: =+IF(F37=12%,D37*H37,0) -> 88.45 | K37: 0 | L37: 0 | M37: =+J37*K37 -> 0 | N37: =+(J37-M37)*F37 -> 10.614 | O37: =+J37-M37+N37 -> 99.064 | P37: INVENTARIO | Q37: 1.1.02.04.001 | R37: INVENTARIO
B38: tpIdProv | C38: 01 | D38: 56.21 | E38: 396-2507 | F38: 0.12 | G38: Bastidor | H38: 2.96 | I38: =+IF(F38=0%,D38*H38,0) -> 0 | J38: =+IF(F38=12%,D38*H38,0) -> 166.3816 | K38: 0 | L38: 0 | M38: =+J38*K38 -> 0 | N38: =+(J38-M38)*F38 -> 19.965792 | O38: =+J38-M38+N38 -> 186.34739 | P38: INVENTARIO | Q38: 1.1.02.04.001 | R38: INVENTARIO
B39: Sustento T | C39: INVENTARIO CREDITO TRIBUTARIO PARA DECLARACION DE IVA | D39: 49 | E39: 396-306 | F39: 0.12 | G39: Tira Color Dorado Con Filos Negros De 7.5 Ancho | H39: 3.15 | I39: =+IF(F39=0%,D39*H39,0) -> 0 | J39: =+IF(F39=12%,D39*H39,0) -> 154.35 | K39: 0 | L39: 0 | M39: =+J39*K39 -> 0 | N39: =+(J39-M39)*F39 -> 18.522 | O39: =+J39-M39+N39 -> 172.872 | P39: INVENTARIO | Q39: 1.1.02.04.001 | R39: INVENTARIO
B40: codSustento | C40: 06 | D40: 12.2 | E40: 362-2889 | F40: 0.12 | G40: Blanca Estucada Semimate | H40: 1.25 | I40: =+IF(F40=0%,D40*H40,0) -> 0 | J40: =+IF(F40=12%,D40*H40,0) -> 15.25 | K40: 0 | L40: 0 | M40: =+J40*K40 -> 0 | N40: =+(J40-M40)*F40 -> 1.83 | O40: =+J40-M40+N40 -> 17.08 | P40: INVENTARIO | Q40: 1.1.02.04.001 | R40: INVENTARIO
B41: Tipo Comp Aut | C41: FACTURA
B42: tipoComprobante | C42: 1
B43: autorizacion | C43: 1120335551 | D43: SUBTOTAL 0% | E43: =+SUM(I37:I40) -> 0
B44: Fecha Emi | C44: 43497 | D44: SUBTOTAL 12% | E44: =+SUM(J37:J42) -> 424.4316
B45: Establecimiento | C45: 001 | D45: DESCUENTO | E45: =SUM(M37:M42) -> 0
...

Sheet VENTAS
A1: Nro Comprobante de autorizacion de Facturas
A2: G-EMPRESA-DOCUMENTOS AUTORIZADOS SRI
A3: Facturación | D3: 123456789
A6: I-SD-R | B6: Deuda | C6: FACTURA VENTA # 1
B7: FACTURA VENTA
B8: Cliente | C8: LEONEL LEMA | D8: CANT | E8: CODIGO | F8: IVA | G8: PRODUCTO/DESCRIP | H8: P. UNI | I8: SUBT 0% | J8: SUBT 12% | K8: DESC % | L8: DESC $ | M8: DESC TOTAL | N8: IVA | O8: TOTAL | P8: CONTABILIDAD | Q8: NRO CUENTA | R8: TIPO | S8: KARDEX P | T8: KARDEX T
B9: idCliente | C9: 1720696275 | D9: 15 | E9: 396-12 | F9: 0.12 | G9: ACEITE DE VASELINA GL.QF | H9: 1.96 | I9: =+IF(F9=0%,D9*H9,0) -> 0 | J9: =+IF(F9=12%,D9*H9,0) -> 29.4 | K9: 0 | L9: 0 | M9: =+J9*K9 -> 0 | N9: =+(J9-M9)*F9 -> 3.528 | O9: =+J9-M9+N9 -> 32.928 | P9: INVENTARIO | Q9: 1.1.02.04.001 | R9: INVENTARIO | S9: =+KARDEX!K83 -> 1.4566071 | T9: =+S9*D9 -> 21.849107
B10: tpIdCliente | C10: 05 | D10: 12.37 | E10: 396-2507 | F10: 0.12 | G10: Bastidor | H10: 4 | I10: =+IF(F10=0%,D10*H10,0) -> 0 | J10: =+IF(F10=12%,D10*H10,0) -> 49.48 | K10: 0 | L10: 0 | M10: =+J10*K10 -> 0 | N10: =+(J10-M10)*F10 -> 5.9376 | O10: =+J10-M10+N10 -> 55.4176 | P10: INVENTARIO | Q10: 1.1.02.04.001 | R10: INVENTARIO | S10: =+KARDEX!K84 -> 2.880272 | T10: =+S10*D10 -> 35.628965
B11: Tipo de Comprobante | C11: Documentos autorizados utilizados en ventas excepto N/C N/D | D11: 22.46 | E11: 396-306 | F11: 0.12 | G11: Tira Color Dorado Con Filos Negros De 7.5 Ancho | H11: 4.39 | I11: =+IF(F11=0%,D11*H11,0) -> 0 | J11: =+IF(F11=12%,D11*H11,0) -> 98.5994 | K11: 0 | L11: 0 | M11: =+J11*K11 -> 0 | N11: =+(J11-M11)*F11 -> 11.831928 | O11: =+J11-M11+N11 -> 110.43133 | P11: INVENTARIO | Q11: 1.1.02.04.001 | R11: INVENTARIO | S11: =+KARDEX!K85 -> 3.2521586 | T11: =+S11*D11 -> 73.043482
B12: tipoComprobante | C12: 18 | D12: 8.67 | E12: 362-2889 | F12: 0.12 | G12: Blanca Estucada Semimate | H12: 1.69 | I12: =+IF(F12=0%,D12*H12,0) -> 0 | J12: =+IF(F12=12%,D12*H12,0) -> 14.6523 | K12: 0 | L12: 0 | M12: =+J12*K12 -> 0 | N12: =+(J12-M12)*F12 -> 1.758276 | O12: =+J12-M12+N12 -> 16.410576 | P12: INVENTARIO | Q12: 1.1.02.04.001 | R12: INVENTARIO | S12: =+KARDEX!K86 -> 1.25 | T12: =+S12*D12 -> 10.8375
B13: Tipo de Emisión | C13: Factura Fisica
B14: tipoEm | C14: f | T14: =SUM(T9:T13) -> 141.35905
B15: Fecha Emi | C15: 43513 | D15: SUBT 0% | E15: =+SUM(I9:I12) -> 0
B16: Establecimiento | C16: 001 | D16: SUBTOTAL 12% | E16: =+SUM(J9:J14) -> 192.1317
B17: Punto Emision | C17: 001 | D17: DESCUENTO | E17: =SUM(M9:M14) -> 0
B18: Secuencial | C18: 100 | D18: IVA | E18: =SUM(N9:N14) -> 23.055804
D19: TOTAL | E19: =SUM(O9:O14) -> 215.1875
B22: RETENCION FACTURA VENTA
B23: Establecimiento Ret1 | C23: 001 | D23: CONTABILIDAD | E23: CUENTA CONT. | G23: BASE IMPONIBLE | H23: IMPUESTO | J23: PORCENTAJE RETENCION | L23: VALOR RET. | M23: TOTAL RET | N23: TOTAL FACT - RET
B24: Pto Emision Ret1 | C24: 001 | D24: 2.1.01.07.006 | E24: Retención IVA 100% | G24: 731 | H24: IVA | J24: 1 | L24: =+E18*J24 -> 23.055804 | M24: =+L24+L25 -> 24.977121 | N24: =+E19-M24 -> 190.21038
B25: Secuencial Ret 1 | C25: 501 | D25: 2.1.01.06.001 | E25: Retención en la fuente 1% | G25: 309 | H25: RENTA | J25: 0.01 | L25: =(E16+E15-E17)*J25 -> 1.921317
B26: Autorizacion | C26: 1123134181
B27: Nro Factura | C27: =+CONCATENATE(C16,"-",C17,"-",C18) -> 001-001-100
B28: Fecha | C28: =+C15 -> 43513 | E28: ASIENTO DIARIO | G28: meti mal la retencion compra
B29: Tipo de Desgloce | C29: Normal | E29: KARDEX | G29: era retencion fuente
B30: Boton | C30: Pendiente
B31: Cuenta Contable | C31: Clientes
B32: Valor a pagar | C32: =+E19-M24 -> 190.21038 | G32: aquí no cuadra el valor pendiente
B33: Estado | C33: Pendiente
A35: I-SD-R | B35: Efectivo | C35: FACTURA VENTA # 2
B36: FACTURA VENTA
B37: Cliente | C37: LEONEL LEMA | D37: CANT | E37: CODIGO | F37: IVA | G37: PRODUCTO/DESCRIP | H37: P. UNI | I37: SUBT 0% | J37: SUBT 12% | K37: DESC % | L37: DESC $ | M37: DESC TOTAL | N37: IVA | O37: TOTAL | P37: CONTABILIDAD | Q37: NRO CUENTA | R37: TIPO | S37: KARDEX P | T37: KARDEX T
B38: idCliente | C38: 1720696275 | D38: 12 | E38: 396-12 | F38: 0.12 | G38: ACEITE DE VASELINA GL.QF | H38: 1.96 | I38: =+IF(F38=0%,D38*H38,0) -> 0 | J38: =+IF(F38=12%,D38*H38,0) -> 23.52 | K38: 0 | L38: 0 | M38: =+J38*K38 -> 0 | N38: =+(J38-M38)*F38 -> 2.8224 | O38: =+J38-M38+N38 -> 26.3424 | P38: INVENTARIO | Q38: 1.1.02.04.001 | R38: INVENTARIO | S38: 1.45 | T38: 21.75
B39: tpIdCliente | C39: 05 | D39: 24 | E39: 396-2507 | F39: 0.12 | G39: Bastidor | H39: 4 | I39: =+IF(F39=0%,D39*H39,0) -> 0 | J39: =+IF(F39=12%,D39*H39,0) -> 96 | K39: 0 | L39: 0 | M39: =+J39*K39 -> 0 | N39: =+(J39-M39)*F39 -> 11.52 | O39: =+J39-M39+N39 -> 107.52 | P39: INVENTARIO | Q39: 1.1.02.04.001 | R39: INVENTARIO | S39: 2.96 | T39: 36.6152
B40: Tipo de Comprobante | C40: Documentos autorizados utilizados en ventas excepto N/C N/D | D40: 2.56 | E40: 396-306 | F40: 0.12 | G40: Tira Color Dorado Con Filos Negros De 7.5 Ancho | H40: 4.39 | I40: =+IF(F40=0%,D40*H40,0) -> 0 | J40: =+IF(F40=12%,D40*H40,0) -> 11.2384 | K40: 0 | L40: 0 | M40: =+J40*K40 -> 0 | N40: =+(J40-M40)*F40 -> 1.348608 | O40: =+J40-M40+N40 -> 12.587008 | P40: INVENTARIO | Q40: 1.1.02.04.001 | R40: INVENTARIO | S40: 3.25 | T40: 72.995
B41: tipoComprobante | C41: 18 | D41: 3.65 | E41: 362-2889 | F41: 0.12 | G41: Blanca Estucada Semimate | H41: 1.69 | I41: =+IF(F41=0%,D41*H41,0) -> 0 | J41: =+IF(F41=12%,D41*H41,0) -> 6.1685 | K41: 0 | L41: 0 | M41: =+J41*K41 -> 0 | N41: =+(J41-M41)*F41 -> 0.74022 | O41: =+J41-M41+N41 -> 6.90872 | P41: INVENTARIO | Q41: 1.1.02.04.001 | R41: INVENTARIO | S41: 1.25 | T41: 10.8375
B42: Tipo de Emisión | C42: Factura Fisica
B43: tipoEm | C43: f | T43: 142.1977
B44: Fecha Emi | C44: 43513 | D44: SUBTOTAL 0% | E44: =+SUM(I38:I41) -> 0
B45: Establecimiento | C45: 001 | D45: SUBTOTAL 12% | E45: =+SUM(J38:J43) -> 136.9269
...

Sheet LIBRO DIARIO
A1: ASIENTO | B1: FECHA | C1: DETALLE TRANSACCION | D1: DETALLE | E1: CUENTA CONTABLE | F1: DEBE | G1: HABER | H1: TOTAL DEBE | I1: TOTAL HABER
A2: 1 | B2: 43497 | C2: ESI AL 1 DE FEBRERO DEL 2019 | D2: Banco XXXXX XXXXX | E2: 1.1.01.02.001 | F2: 1200 | H2: 41669.976 | I2: 41669.976
D3: Inventario | E3: 1.1.02.04.001 | F3: 26769.976
D4: Terrenos | E4: 1.2.01.03.001 | F4: 12500
D5: Equipo de oficina | E5: 1.2.01.01.001 | F5: 1200
D6: Cuentas por Pagar | E6: 2.1.01.01.002 | G6: 400
D7: Préstamos bancarios | E7: 2.1.01.04.001 | G7: 3000
D8: Capital | E8: 3.1.01.01.001 | G8: 38269.976
A9: 2 | B9: =+[1]COMPRAS!B16 -> 43497 | C9: =+[1]COMPRAS!B6 -> FACTURA COMPRA # 1 | D9: Inventario | E9: 1.1.02.04.001 | F9: =+COMPRAS!E16+COMPRAS!E15-COMPRAS!E17 -> 424.4316 | H9: =+SUM(F9:F13) -> 475.36339 | I9: =+SUM(G9:G13) -> 475.36339 | J9: VOLVER A FACTURA
D10: Iva pagado | E10: 1.1.02.06.001 | F10: =+COMPRAS!E18 -> 50.931792
D11: =+COMPRAS!E24 -> Retencion IVA por pagar 100% | E11: =+COMPRAS!D24 -> 2.1.01.07.006 | G11: =+COMPRAS!L24 -> 50.931792
D12: =+COMPRAS!E25 -> Impuesto a la renta por pagar 1% | E12: =+COMPRAS!D25 -> 2.1.01.06.001 | G12: =+COMPRAS!L25 -> 4.244316
D13: Proveedores | G13: =+COMPRAS!N24 -> 420.18728
A14: 3 | B14: =+COMPRAS!C44 -> 43497 | C14: =+COMPRAS!C34 -> FACTURA COMPRA # 2 | D14: Inventario | E14: 1.1.02.04.001 | F14: =+COMPRAS!E44+COMPRAS!E43-COMPRAS!E45 -> 424.4316 | H14: =+SUM(F14:F18) -> 475.36339 | I14: =+SUM(G14:G18) -> 475.36339 | J14: VOLVER A FACTURA
D15: Iva pagado | E15: 1.1.02.06.001 | F15: =+COMPRAS!E46 -> 50.931792
D16: =+COMPRAS!E52 -> Retencion IVA por pagar 30% | E16: =+COMPRAS!D52 -> 2.1.01.07.003 | G16: =+COMPRAS!L52 -> 15.279538
D17: =+COMPRAS!E53 -> Impuesto a la renta por pagar 8% | E17: =+COMPRAS!D53 -> 2.1.01.06.003 | G17: =+COMPRAS!L53 -> 33.954528
D18: Proveedores | G18: =+COMPRAS!N52 -> 426.12933
A19: 4 | B19: =+B14 -> 43497 | C19: =+C14 -> FACTURA COMPRA # 2 | D19: Proveedores | F19: =+G18 -> 426.12933 | H19: =+SUM(F19:F20) -> 426.12933 | I19: =+SUM(G19:G20) -> 426.12933
D20: =+COMPRAS!C58 -> Caja General | G20: =+COMPRAS!C59 -> 426.12933
A21: 5 | B21: =+COMPRAS!C72 -> 43497 | C21: =+COMPRAS!C62 -> FACTURA COMPRA # 3 | D21: Inventario | E21: 1.1.02.04.001 | F21: =+COMPRAS!E72+COMPRAS!E71-COMPRAS!E73 -> 424.4316 | H21: =+SUM(F21:F25) -> 475.36339 | I21: =+SUM(G21:G25) -> 475.36339 | J21: VOLVER A FACTURA
D22: Iva pagado | E22: 1.1.02.06.001 | F22: =+COMPRAS!E74 -> 50.931792
D23: =+COMPRAS!E80 -> Retencion IVA por pagar 50% | E23: =+COMPRAS!D80 -> 2.1.01.07.004 | G23: =+COMPRAS!L80 -> 25.465896
D24: =+COMPRAS!E81 -> Impuesto a la renta por pagar 2% | E24: =+COMPRAS!D81 -> 2.1.01.06.002 | G24: =+COMPRAS!L81 -> 8.488632
D25: Proveedores | E25: 2.1.01.01.001 | G25: =+COMPRAS!N80 -> 441.40886
A26: 6 | B26: =+B21 -> 43497 | C26: =+C21 -> FACTURA COMPRA # 3 | D26: Proveedores | E26: 2.1.01.01.001 | F26: =+G25 -> 441.40886 | H26: =+SUM(F26:F27) -> 441.40886 | I26: =+SUM(G26:G27) -> 441.40886
D27: Tarjetas de Credito | E27: 5.2.01.10.001 | G27: =+COMPRAS!C87 -> 441.40886
A28: 7 | B28: =+COMPRAS!C100 -> 43498 | C28: =+COMPRAS!C90 -> FACTURA COMPRA # 4 | D28: Inventario | E28: 1.1.02.04.001 | F28: =+COMPRAS!E99+COMPRAS!E100-COMPRAS!E101 -> 1180.8087 | H28: =+SUM(F28:F32) -> 1322.5057 | I28: =+SUM(G28:G32) -> 1322.5057 | J28: VOLVER A FACTURA
D29: Iva pagado | E29: 1.1.02.06.001 | F29: =+COMPRAS!E102 -> 141.69704
D30: =+COMPRAS!E108 -> Retencion IVA por pagar 70% | E30: =+COMPRAS!D108 -> 2.1.01.07.005 | G30: =+COMPRAS!L108 -> 99.187931
D31: =+COMPRAS!E109 -> Impuesto a la renta por pagar 1% | E31: =+COMPRAS!D109 -> 2.1.01.06.001 | G31: =+COMPRAS!L109 -> 11.808087
D32: Proveedores | G32: =+COMPRAS!N108 -> 1211.5097
A33: 8 | B33: =+B28 -> 43498 | C33: =+C28 -> FACTURA COMPRA # 4 | D33: Proveedores | F33: =+G32 -> 1211.5097 | H33: =+SUM(F33:F34) -> 1211.5097 | I33: =+SUM(G33:G34) -> 1211.5097
D34: =+COMPRAS!C114 -> Bancos XXX XXXX | G34: =+COMPRAS!C115 -> 1211.5097
A35: 9 | B35: =+COMPRAS!C128 -> 43498 | C35: =+COMPRAS!C118 -> FACTURA COMPRA # 5 | D35: Inventario | E35: 1.1.02.04.001 | F35: =+COMPRAS!E127+COMPRAS!E128-COMPRAS!E129 -> 1180.8087 | H35: =+SUM(F35:F39) -> 1322.5057 | I35: =+SUM(G35:G39) -> 1322.5057 | J35: VOLVER A FACTURA
D36: Iva pagado | E36: 1.1.02.06.001 | F36: =+COMPRAS!E130 -> 141.69704
D37: =+COMPRAS!E136 -> Retencion IVA por pagar 10% | E37: =+COMPRAS!D136 -> 2.1.01.07.001 | G37: =+COMPRAS!L136 -> 14.169704
D38: =+COMPRAS!E137 -> Impuesto a la renta por pagar 8% | E38: =+COMPRAS!D137 -> 2.1.01.06.003 | G38: =+COMPRAS!L137 -> 94.464696
D39: Proveedores | G39: =+COMPRAS!N136 -> 1213.8713
A40: 10 | B40: =+B35 -> 43498 | C40: =+C35 -> FACTURA COMPRA # 5 | D40: Proveedores | F40: =+G39 -> 1213.8713 | H40: =+SUM(F40:F43) -> 1213.8713 | I40: =+SUM(G40:G43) -> 1213.8713
...

Sheet Hoja4
A1: ASIENTO | B1: FECHA | C1: DETALLE TRANSACCION | D1: DETALLE | E1: CUENTA CONTABLE | F1: DEBE | G1: HABER | H1: TOTAL DEBE | I1: TOTAL HABER
A2: 79 | B2: =+VENTAS!C15 -> 43513 | C2: =+VENTAS!C6 -> FACTURA VENTA # 1 | D2: =+VENTAS!C31 -> Clientes | F2: =+VENTAS!N24 -> 190.21038 | H2: =+SUM(F2:F5) -> 215.1875 | I2: =+SUM(G2:G6) -> 215.1875 | J2: VOLVER A FACTURA
D3: =+VENTAS!E24 -> Retención IVA 100% | E3: =+VENTAS!D24 -> 2.1.01.07.006 | F3: =+VENTAS!L24 -> 23.055804
D4: =+VENTAS!E25 -> Retención en la fuente 1% | E4: =+VENTAS!D25 -> 2.1.01.06.001 | F4: =+VENTAS!L25 -> 1.921317
D5: Iva pagado | E5: 1.1.02.06.001 | G5: =+VENTAS!E18 -> 23.055804
D6: Ventas | G6: =+VENTAS!E15+VENTAS!E16-VENTAS!E17 -> 192.1317
A7: 80 | B7: =+B2 -> 43513 | C7: =+C2 -> FACTURA VENTA # 1 | D7: Costo de venta inventario | F7: =+VENTAS!T14 -> 141.35905 | H7: =+SUM(F7:F8) -> 141.35905 | I7: =+SUM(G7:G8) -> 141.35905
D8: Inventario | E8: 1.1.02.04.001 | G8: =+VENTAS!T14 -> 141.35905
A9: 81 | B9: =+VENTAS!C44 -> 43513 | C9: =+VENTAS!C35 -> FACTURA VENTA # 2 | D9: =+VENTAS!C31 -> Clientes | F9: =+VENTAS!N53 -> 137.47461 | H9: =+SUM(F9:F12) -> 153.35813 | I9: =+SUM(G9:G13) -> 153.35813 | J9: VOLVER A FACTURA
D10: =+VENTAS!E53 -> Retencion IVA 30% | E10: =+VENTAS!D53 -> 2.1.01.07.003 | F10: =+VENTAS!L53 -> 4.9293684
D11: =+VENTAS!E54 -> Retención en la fuente 8% | E11: =+VENTAS!D54 -> 2.1.01.06.003 | F11: =+VENTAS!L54 -> 10.954152
D12: Iva pagado | E12: 1.1.02.06.001 | G12: =+VENTAS!E47 -> 16.431228
D13: Ventas | G13: =+VENTAS!E44+VENTAS!E45-VENTAS!E46 -> 136.9269
A14: 82 | B14: =+B9 -> 43513 | C14: =+C9 -> FACTURA VENTA # 2 | D14: =+VENTAS!C60 -> Caja General | F14: =+VENTAS!C61 -> 137.47461 | H14: =+SUM(G14:G15) -> 137.47461 | I14: =+SUM(F14:F15) -> 137.47461
D15: Clientes | G15: =+F9 -> 137.47461
A16: 83 | B16: =+B14 -> 43513 | C16: =+C14 -> FACTURA VENTA # 2 | D16: Costo de venta inventario | F16: =+VENTAS!T43 -> 142.1977 | H16: =+SUM(F16:F17) -> 142.1977 | I16: =+SUM(G16:G17) -> 142.1977
D17: Inventario | E17: 1.1.02.04.001 | G17: =+VENTAS!T43 -> 142.1977
A18: 84 | B18: =+VENTAS!C73 -> 43513 | C18: =+VENTAS!C64 -> FACTURA VENTA # 3 | D18: Clientes | F18: =+VENTAS!N82 -> 332.73042 | H18: =+SUM(F18:F21) -> 358.32507 | I18: =+SUM(G18:G22) -> 358.32507 | J18: VOLVER A FACTURA
D19: =+VENTAS!E82 -> Retención IVA 50% | F19: =+VENTAS!L82 -> 19.195986
D20: =+VENTAS!E83 -> Retención en la fuente 2% | F20: =+VENTAS!L83 -> 6.398662
D21: Iva pagado | E21: 1.1.02.06.001 | G21: =+VENTAS!E76 -> 38.391972
D22: Ventas | G22: =+VENTAS!E73+VENTAS!E74-VENTAS!E75 -> 319.9331
A23: 85 | B23: =+B18 -> 43513 | C23: =+C18 -> FACTURA VENTA # 3 | D23: =+VENTAS!C88 -> Tarjeta de Credito | F23: =+VENTAS!C90 -> 332.73042 | H23: =+SUM(G23:G24) -> 332.73042 | I23: =+SUM(F23:F24) -> 332.73042
D24: Clientes | G24: =+VENTAS!C90 -> 332.73042
A25: 86 | B25: =+B23 -> 43513 | C25: =+C23 -> FACTURA VENTA # 3 | D25: Costo de venta inventario | F25: =+VENTAS!T72 -> 142.1977 | H25: =+SUM(F25:F26) -> 142.1977 | I25: =+SUM(G25:G26) -> 142.1977
D26: Inventario | E26: 1.1.02.04.001 | G26: =+VENTAS!T72 -> 142.1977
A27: 7 | B27: =+VENTAS!C103 -> 43513 | C27: =+VENTAS!C93 -> FACTURA VENTA # 4 | D27: Inventario | E27: 1.1.02.04.001 | G27: =+VENTAS!E102+VENTAS!E103-VENTAS!E104 -> 1180.8087 | H27: =+SUM(G27:G31) -> 1322.5057 | I27: =+SUM(F27:F31) -> 1322.5057 | J27: VOLVER A FACTURA
D28: Iva pagado | E28: 1.1.02.06.001 | G28: =+VENTAS!E105 -> 141.69704
D29: =+VENTAS!E111 -> Retención IVA 70% | E29: =+VENTAS!D111 -> 2.1.01.07.005 | F29: =+VENTAS!L111 -> 99.187931
D30: =+VENTAS!E112 -> Retención en la fuente 1% | E30: =+VENTAS!D112 -> 2.1.01.06.001 | F30: =+VENTAS!L112 -> 11.808087
D31: Proveedores | F31: =+VENTAS!N111 -> 1211.5097
A32: 8 | B32: =+B27 -> 43513 | C32: =+C27 -> FACTURA VENTA # 4 | D32: Proveedores | G32: =+F31 -> 1211.5097 | H32: =+SUM(G32:G33) -> 1211.5097 | I32: =+SUM(F32:F33) -> 1211.5097
D33: =+VENTAS!C117 -> Bancos XXX XXXX | F33: =+VENTAS!C118 -> 1211.5097
A34: 9 | B34: =+VENTAS!C131 -> 43513 | C34: =+VENTAS!C121 -> FACTURA VENTA # 5 | D34: Inventario | E34: 1.1.02.04.001 | G34: =+VENTAS!E130+VENTAS!E131-VENTAS!E132 -> 1180.8087 | H34: =+SUM(G34:G38) -> 1322.5057 | I34: =+SUM(F34:F38) -> 1322.5057 | J34: VOLVER A FACTURA
D35: Iva pagado | E35: 1.1.02.06.001 | G35: =+VENTAS!E133 -> 141.69704
D36: =+VENTAS!E139 -> Retención IVA 10% | E36: =+VENTAS!D139 -> 2.1.01.07.001 | F36: =+VENTAS!L139 -> 14.169704
D37: =+VENTAS!E140 -> Retención en la fuente 8% | E37: =+VENTAS!D140 -> 2.1.01.06.003 | F37: =+VENTAS!L140 -> 94.464696
D38: Proveedores | F38: =+VENTAS!N139 -> 1213.8713
A39: 10 | B39: =+B34 -> 43513 | C39: =+C34 -> FACTURA VENTA # 5 | D39: Proveedores | G39: =+F38 -> 1213.8713 | H39: =+SUM(G39:G42) -> 1213.8713 | I39: =+SUM(F39:F42) -> 1213.8713
D40: =+VENTAS!C145 -> Bancos XXX XXXX | F40: =+VENTAS!C146 -> 364.1614
...

Sheet KARDEX
D1: INGRESO | G1: EGRESO | J1: SALDOS
A2: FECHA | B2: DETALLE TRANSACCION | C2: DETALLE | D2: CANT | E2: VALOR | F2: TOTAL | G2: CANT | H2: VALOR | I2: TOTAL | J2: CANT | K2: VALOR | L2: TOTAL
A3: =+[1]COMPRAS!B153 -> 43504 | B3: =+CONCATENATE(COMPRAS!C6," ",COMPRAS!C26) -> FACTURA COMPRA # 1 001-001-100 | C3: =+COMPRAS!G9 -> ACEITE DE VASELINA GL.QF | D3: =+COMPRAS!D9 -> 61 | E3: =+COMPRAS!H9 -> 1.45 | F3: =+D3*E3 -> 88.45 | J3: =+D3 -> 61 | K3: =+E3 -> 1.45 | L3: =+F3 -> 88.45 | M3: REGRESAR A FACTURA
C4: =+COMPRAS!G10 -> Bastidor | D4: =+COMPRAS!D10 -> 56.21 | E4: =+COMPRAS!H10 -> 2.96 | F4: =+D4*E4 -> 166.3816 | J4: =+D4 -> 56.21 | K4: =+E4 -> 2.96 | L4: =+F4 -> 166.3816
C5: =+COMPRAS!G11 -> Tira Color Dorado Con Filos Negros De 7.5 Ancho | D5: =+COMPRAS!D11 -> 49 | E5: =+COMPRAS!H11 -> 3.15 | F5: =+D5*E5 -> 154.35 | J5: =+D5 -> 49 | K5: =+E5 -> 3.15 | L5: =+F5 -> 154.35
C6: =+COMPRAS!G12 -> Blanca Estucada Semimate | D6: =+COMPRAS!D12 -> 12.2 | E6: =+COMPRAS!H12 -> 1.25 | F6: =+D6*E6 -> 15.25 | J6: =+D6 -> 12.2 | K6: =+E6 -> 1.25 | L6: =+F6 -> 15.25
A7: =+COMPRAS!C44 -> 43497 | B7: =+CONCATENATE(COMPRAS!C34," ",COMPRAS!C54) -> FACTURA COMPRA # 2 001-001-101 | C7: =+COMPRAS!G37 -> ACEITE DE VASELINA GL.QF | D7: =+COMPRAS!D37 -> 61 | E7: =+COMPRAS!H37 -> 1.45 | F7: =+D7*E7 -> 88.45 | J7: =+J3+D7 -> 122 | K7: =+L7/J7 -> 1.45 | L7: =+L3+F7 -> 176.9 | M7: REGRESAR A FACTURA
C8: =+COMPRAS!G38 -> Bastidor | D8: =+COMPRAS!D38 -> 56.21 | E8: =+COMPRAS!H38 -> 2.96 | F8: =+D8*E8 -> 166.3816 | J8: =+J4+D8 -> 112.42 | K8: =+L8/J8 -> 2.96 | L8: =+L4+F8 -> 332.7632
C9: =+COMPRAS!G39 -> Tira Color Dorado Con Filos Negros De 7.5 Ancho | D9: =+COMPRAS!D39 -> 49 | E9: =+COMPRAS!H39 -> 3.15 | F9: =+D9*E9 -> 154.35 | J9: =+J5+D9 -> 98 | K9: =+L9/J9 -> 3.15 | L9: =+L5+F9 -> 308.7
C10: =+COMPRAS!G40 -> Blanca Estucada Semimate | D10: =+COMPRAS!D40 -> 12.2 | E10: =+COMPRAS!H40 -> 1.25 | F10: =+D10*E10 -> 15.25 | J10: =+J6+D10 -> 24.4 | K10: =+L10/J10 -> 1.25 | L10: =+L6+F10 -> 30.5
A11: =+COMPRAS!C72 -> 43497 | B11: =+CONCATENATE(COMPRAS!C62," ",COMPRAS!C82) -> FACTURA COMPRA # 3 001-001-102 | C11: =+COMPRAS!G65 -> ACEITE DE VASELINA GL.QF | D11: =+COMPRAS!D65 -> 61 | E11: =+COMPRAS!H65 -> 1.45 | F11: =+D11*E11 -> 88.45 | J11: =+J7+D11 -> 183 | K11: =+L11/J11 -> 1.45 | L11: =+L7+F11 -> 265.35 | M11: REGRESAR A FACTURA
C12: =+COMPRAS!G66 -> Bastidor | D12: =+COMPRAS!D66 -> 56.21 | E12: =+COMPRAS!H66 -> 2.96 | F12: =+D12*E12 -> 166.3816 | J12: =+J8+D12 -> 168.63 | K12: =+L12/J12 -> 2.96 | L12: =+L8+F12 -> 499.1448
C13: =+COMPRAS!G67 -> Tira Color Dorado Con Filos Negros De 7.5 Ancho | D13: =+COMPRAS!D67 -> 49 | E13: =+COMPRAS!H67 -> 3.15 | F13: =+D13*E13 -> 154.35 | J13: =+J9+D13 -> 147 | K13: =+L13/J13 -> 3.15 | L13: =+L9+F13 -> 463.05
C14: =+COMPRAS!G68 -> Blanca Estucada Semimate | D14: =+COMPRAS!D68 -> 12.2 | E14: =+COMPRAS!H68 -> 1.25 | F14: =+D14*E14 -> 15.25 | J14: =+J10+D14 -> 36.6 | K14: =+L14/J14 -> 1.25 | L14: =+L10+F14 -> 45.75
A15: =+COMPRAS!C100 -> 43498 | B15: =+CONCATENATE(COMPRAS!C90," ",COMPRAS!C110) -> FACTURA COMPRA # 4 001-001-103 | C15: =+COMPRAS!G93 -> Azúl Con Dorado | D15: =+COMPRAS!D93 -> 118.47 | E15: =+COMPRAS!H93 -> 1.47 | F15: =+D15*E15 -> 174.1509 | J15: =+D15 -> 118.47 | K15: =+E15 -> 1.47 | L15: =+F15 -> 174.1509 | M15: REGRESAR A FACTURA
C16: =+COMPRAS!G94 -> pino natural procesado con ceja izq | D16: =+COMPRAS!D94 -> 249.58 | E16: =+COMPRAS!H94 -> 2.96 | F16: =+D16*E16 -> 738.7568 | J16: =+D16 -> 249.58 | K16: =+E16 -> 2.96 | L16: =+F16 -> 738.7568
C17: =+COMPRAS!G95 -> pino natural peq. Procesado ceja | D17: =+COMPRAS!D95 -> 73.54 | E17: =+COMPRAS!H95 -> 3.15 | F17: =+D17*E17 -> 231.651 | J17: =+D17 -> 73.54 | K17: =+E17 -> 3.15 | L17: =+F17 -> 231.651
C18: =+COMPRAS!G96 -> pino natural procesado con ceja der | D18: =+COMPRAS!D96 -> 29 | E18: =+COMPRAS!H96 -> 1.25 | F18: =+D18*E18 -> 36.25 | J18: =+D18 -> 29 | K18: =+E18 -> 1.25 | L18: =+F18 -> 36.25
A19: =+COMPRAS!C128 -> 43498 | B19: =+CONCATENATE(COMPRAS!C118," ",COMPRAS!C138) -> FACTURA COMPRA # 5 001-001-104 | C19: =+COMPRAS!G121 -> Azúl Con Dorado | D19: =+COMPRAS!D121 -> 118.47 | E19: =+COMPRAS!H121 -> 1.47 | F19: =+D19*E19 -> 174.1509 | J19: =+J15+D19 -> 236.94 | K19: =+L19/J19 -> 1.47 | L19: =+L15+F19 -> 348.3018 | M19: REGRESAR A FACTURA
C20: =+COMPRAS!G122 -> pino natural procesado con ceja izq | D20: =+COMPRAS!D122 -> 249.58 | E20: =+COMPRAS!H122 -> 2.96 | F20: =+D20*E20 -> 738.7568 | J20: =+J16+D20 -> 499.16 | K20: =+L20/J20 -> 2.96 | L20: =+L16+F20 -> 1477.5136
C21: =+COMPRAS!G123 -> pino natural peq. Procesado ceja | D21: =+COMPRAS!D123 -> 73.54 | E21: =+COMPRAS!H123 -> 3.15 | F21: =+D21*E21 -> 231.651 | J21: =+J17+D21 -> 147.08 | K21: =+L21/J21 -> 3.15 | L21: =+L17+F21 -> 463.302
C22: =+COMPRAS!G124 -> pino natural procesado con ceja der | D22: =+COMPRAS!D124 -> 29 | E22: =+COMPRAS!H124 -> 1.25 | F22: =+D22*E22 -> 36.25 | J22: =+J18+D22 -> 58 | K22: =+L22/J22 -> 1.25 | L22: =+L18+F22 -> 72.5
A23: =+COMPRAS!C161 -> 43498 | B23: =+CONCATENATE(COMPRAS!C151," ",COMPRAS!C171) -> FACTURA COMPRA # 6 001-001-105 | C23: =+COMPRAS!G154 -> Azúl Con Dorado | D23: =+COMPRAS!D154 -> 118.47 | E23: =+COMPRAS!H154 -> 1.47 | F23: =+D23*E23 -> 174.1509 | J23: =+J19+D23 -> 355.41 | K23: =+L23/J23 -> 1.47 | L23: =+L19+F23 -> 522.4527 | M23: REGRESAR A FACTURA
C24: =+COMPRAS!G155 -> pino natural procesado con ceja izq | D24: =+COMPRAS!D155 -> 249.58 | E24: =+COMPRAS!H155 -> 2.96 | F24: =+D24*E24 -> 738.7568 | J24: =+J20+D24 -> 748.74 | K24: =+L24/J24 -> 2.96 | L24: =+L20+F24 -> 2216.2704
C25: =+COMPRAS!G156 -> pino natural peq. Procesado ceja | D25: =+COMPRAS!D156 -> 73.54 | E25: =+COMPRAS!H156 -> 3.15 | F25: =+D25*E25 -> 231.651 | J25: =+J21+D25 -> 220.62 | K25: =+L25/J25 -> 3.15 | L25: =+L21+F25 -> 694.953
C26: =+COMPRAS!G157 -> pino natural procesado con ceja der | D26: =+COMPRAS!D157 -> 29 | E26: =+COMPRAS!H157 -> 1.25 | F26: =+D26*E26 -> 36.25 | J26: =+J22+D26 -> 87 | K26: =+L26/J26 -> 1.25 | L26: =+L22+F26 -> 108.75
A27: =+COMPRAS!C192 -> 43497 | B27: =+CONCATENATE(COMPRAS!C182," ",COMPRAS!C193,"-",COMPRAS!C194,"-",COMPRAS!C195) -> FACTURA COMPRA # 7 001-001-106 | C27: =+COMPRAS!G185 -> ACEITE DE VASELINA GL.QF | D27: =+COMPRAS!D185 -> 61 | E27: =+COMPRAS!H185 -> 1.45 | F27: =+D27*E27 -> 88.45 | J27: =+J11+D27 -> 244 | K27: =+L27/J27 -> 1.45 | L27: =+L11+F27 -> 353.8 | M27: REGRESAR A FACTURA
C28: =+COMPRAS!G186 -> Bastidor | D28: =+COMPRAS!D186 -> 56.21 | E28: =+COMPRAS!H186 -> 2.96 | F28: =+D28*E28 -> 166.3816 | J28: =+J12+D28 -> 224.84 | K28: =+L28/J28 -> 2.96 | L28: =+L12+F28 -> 665.5264
C29: =+COMPRAS!G187 -> Tira Color Dorado Con Filos Negros De 7.5 Ancho | D29: =+COMPRAS!D187 -> 49 | E29: =+COMPRAS!H187 -> 3.15 | F29: =+D29*E29 -> 154.35 | J29: =+J13+D29 -> 196 | K29: =+L29/J29 -> 3.15 | L29: =+L13+F29 -> 617.4
C30: =+COMPRAS!G188 -> Blanca Estucada Semimate | D30: =+COMPRAS!D188 -> 12.2 | E30: =+COMPRAS!H188 -> 1.25 | F30: =+D30*E30 -> 15.25 | J30: =+J14+D30 -> 48.8 | K30: =+L30/J30 -> 1.25 | L30: =+L14+F30 -> 61
A31: =+COMPRAS!C215 -> 43497 | B31: =+CONCATENATE(COMPRAS!C205," ",COMPRAS!C216,"-",COMPRAS!C217,"-",COMPRAS!C218) -> FACTURA COMPRA # 8 001-001-107 | C31: =+COMPRAS!G208 -> ACEITE DE VASELINA GL.QF | D31: =+COMPRAS!D208 -> 61 | E31: =+COMPRAS!H208 -> 1.45 | F31: =+D31*E31 -> 88.45 | J31: =+J27+D31 -> 305 | K31: =+L31/J31 -> 1.45 | L31: =+L27+F31 -> 442.25 | M31: REGRESAR A FACTURA
C32: =+COMPRAS!G209 -> Bastidor | D32: =+COMPRAS!D209 -> 56.21 | E32: =+COMPRAS!H209 -> 2.96 | F32: =+D32*E32 -> 166.3816 | J32: =+J28+D32 -> 281.05 | K32: =+L32/J32 -> 2.96 | L32: =+L28+F32 -> 831.908
C33: =+COMPRAS!G210 -> Tira Color Dorado Con Filos Negros De 7.5 Ancho | D33: =+COMPRAS!D210 -> 49 | E33: =+COMPRAS!H210 -> 4.73 | F33: =+D33*E33 -> 231.77 | J33: =+J29+D33 -> 245 | K33: =+L33/J33 -> 3.466 | L33: =+L29+F33 -> 849.17
C34: =+COMPRAS!G211 -> Blanca Estucada Semimate | D34: =+COMPRAS!D211 -> 12.2 | E34: =+COMPRAS!H211 -> 1.25 | F34: =+D34*E34 -> 15.25 | J34: =+J30+D34 -> 61 | K34: =+L34/J34 -> 1.25 | L34: =+L30+F34 -> 76.25
A35: =+COMPRAS!C238 -> 43497 | B35: =+CONCATENATE(COMPRAS!C228," ",COMPRAS!C239,"-",COMPRAS!C240,"-",COMPRAS!C241) -> FACTURA COMPRA # 9 001-001-108 | C35: =+COMPRAS!G231 -> ACEITE DE VASELINA GL.QF | D35: =+COMPRAS!D231 -> 61 | E35: =+COMPRAS!H231 -> 1.45 | F35: =+D35*E35 -> 88.45 | J35: =+J31+D35 -> 366 | K35: =+L35/J35 -> 1.45 | L35: =+L31+F35 -> 530.7 | M35: REGRESAR A FACTURA
C36: =+COMPRAS!G232 -> Bastidor | D36: =+COMPRAS!D232 -> 56.21 | E36: =+COMPRAS!H232 -> 2.96 | F36: =+D36*E36 -> 166.3816 | J36: =+J32+D36 -> 337.26 | K36: =+L36/J36 -> 2.96 | L36: =+L32+F36 -> 998.2896
C37: =+COMPRAS!G233 -> Tira Color Dorado Con Filos Negros De 7.5 Ancho | D37: =+COMPRAS!D233 -> 49 | E37: =+COMPRAS!H233 -> 2.77 | F37: =+D37*E37 -> 135.73 | J37: =+J33+D37 -> 294 | K37: =+L37/J37 -> 3.35 | L37: =+L33+F37 -> 984.9
C38: =+COMPRAS!G234 -> Blanca Estucada Semimate | D38: =+COMPRAS!D234 -> 12.2 | E38: =+COMPRAS!H234 -> 1.25 | F38: =+D38*E38 -> 15.25 | J38: =+J34+D38 -> 73.2 | K38: =+L38/J38 -> 1.25 | L38: =+L34+F38 -> 91.5
A39: =+COMPRAS!C261 -> 43498 | B39: =+CONCATENATE(COMPRAS!C251," ",COMPRAS!C262,"-",COMPRAS!C263,"-",COMPRAS!C264) -> FACTURA COMPRA # 10 001-001-109 | C39: =+COMPRAS!G254 -> Azúl Con Dorado | D39: =+COMPRAS!D254 -> 118.47 | E39: =+COMPRAS!H254 -> 1.47 | F39: =+D39*E39 -> 174.1509 | J39: =+J23+D39 -> 473.88 | K39: =+L39/J39 -> 1.47 | L39: =+L23+F39 -> 696.6036 | M39: REGRESAR A FACTURA
C40: =+COMPRAS!G255 -> pino natural procesado con ceja izq | D40: =+COMPRAS!D255 -> 249.58 | E40: =+COMPRAS!H255 -> 2.96 | F40: =+D40*E40 -> 738.7568 | J40: =+J24+D40 -> 998.32 | K40: =+L40/J40 -> 2.96 | L40: =+L24+F40 -> 2955.0272
...
